<mujoco model="torobo2_standard">
  <compiler angle="radian" meshdir="torobo2/meshes" autolimits="true"/>
  <option timestep='0.001' integrator="implicitfast"/>
  <statistic meansize="0.169328" extent="2.00894" center="-0.00792332 4.8352e-07 0.725047"/>

  <default>
    <default class="torobo2">
      <joint armature="0.1" stiffness="0" damping="0"/>
      <default class="visual">
        <geom type="mesh" contype="0" conaffinity="0" group="2" density="0"/>
      </default>
      <default class="collision">
        <geom type="mesh" contype="1" conaffinity="1" group="3" rgba="1 1 1 1"/>
      </default>
    </default>

    <default class="humanoid">
      <geom contype="1" conaffinity="1"/>
      <default class="c_human_right-arm">
        <!-- <geom contype="1" conaffinity="62" /> -->
        <geom contype="1" conaffinity="1"/>
      </default>
      <default class="c_human_upper-body">
        <!-- <geom contype="2" conaffinity="57" /> -->
        <geom contype="1" conaffinity="1"/>
      </default>
      <default class="c_human_lower-body">
        <!-- <geom contype="4" conaffinity="121"/> -->
        <geom contype="1" conaffinity="1"/>
      </default>
      <default class="no-c_human">
        <!-- <geom contype="0" conaffinity="0"/> -->
        <geom contype="1" conaffinity="1"/>
      </default>
      <joint armature="1" damping="1" limited="true"/>
      <general dyntype="none" biastype="affine" ctrlrange="-.4 .4" ctrllimited="true"/>
      <material specular="0.5" rgba="0.4 0.33 0.26 1.0"/>
    </default>
  </default>

  <asset>
    <texture name="texplane" type="2d" builtin="checker" rgb1=".2 .3 .4" rgb2=".1 0.15 0.2"
          width="512" height="512" mark="cross" markrgb=".8 .8 .8"/>
    <material name="matplane" reflectance="0." texture="texplane" texrepeat="1 1" texuniform="true"/>

    <material name="219,219,219" specular="0.8588239999999999" shininess="1.0" rgba="0.858824 0.858824 0.858824 1.000000"/>
    <material name="210,210,210" specular="1.0" shininess="0.2" rgba="0.823529 0.823529 0.823529 1.000000"/>
    <material name="72,71,61" specular="0.26666666666666666" shininess="1.0" rgba="0.282353 0.278431 0.239216 1.000000"/>
    <material name="192,192,192" specular="1.0" shininess="0.2" rgba="0.752941 0.752941 0.752941 1.000000"/>
    <material name="190,188,186" specular="1.0" shininess="0.2" rgba="0.745098 0.737255 0.729412 1.000000"/>

    <!-- visual meshes -->
    <mesh name="base_link" file="visual/base_link.obj"/>
    <mesh name="right_wheel_link_0" file="visual/right_wheel_link_0.obj"/>
    <mesh name="right_wheel_link_1" file="visual/right_wheel_link_1.obj"/>
    <mesh name="left_wheel_link_0" file="visual/left_wheel_link_0.obj"/>
    <mesh name="left_wheel_link_1" file="visual/left_wheel_link_1.obj"/>
    <mesh name="torso_link0" file="visual/torso_link0.obj"/>
    <mesh name="torso_link1_0" file="visual/torso_link1_0.obj"/>
    <mesh name="torso_link1_1" file="visual/torso_link1_1.obj"/>
    <mesh name="torso_link2" file="visual/torso_link2.obj"/>
    <mesh name="torso_link3" file="visual/torso_link3.obj"/>
    <mesh name="head_link1" file="visual/head_link1.obj"/>
    <mesh name="head_link2" file="visual/head_link2.obj"/>
    <mesh name="head_link3_0" file="visual/head_link3_0.obj"/>
    <mesh name="head_link3_1" file="visual/head_link3_1.obj"/>
    <mesh name="left_arm_link0" file="visual/left_arm_link0.obj"/>
    <mesh name="left_arm_link1_0" file="visual/left_arm_link1_0.obj"/>
    <mesh name="left_arm_link1_1" file="visual/left_arm_link1_1.obj"/>
    <mesh name="left_arm_link2" file="visual/left_arm_link2.obj"/>
    <mesh name="left_arm_link3_0" file="visual/left_arm_link3_0.obj"/>
    <mesh name="left_arm_link3_1" file="visual/left_arm_link3_1.obj"/>
    <mesh name="left_arm_link4" file="visual/left_arm_link4.obj"/>
    <mesh name="left_arm_link5" file="visual/left_arm_link5.obj"/>
    <mesh name="left_arm_link6" file="visual/left_arm_link6.obj"/>
    <mesh name="left_arm_link7" file="visual/left_arm_link7.obj"/>
    <mesh name="right_arm_link0" file="visual/right_arm_link0.obj"/>
    <mesh name="right_arm_link1_0" file="visual/right_arm_link1_0.obj"/>
    <mesh name="right_arm_link1_1" file="visual/right_arm_link1_1.obj"/>
    <mesh name="right_arm_link2" file="visual/right_arm_link2.obj"/>
    <mesh name="right_arm_link3_0" file="visual/right_arm_link3_0.obj"/>
    <mesh name="right_arm_link3_1" file="visual/right_arm_link3_1.obj"/>
    <mesh name="right_arm_link4" file="visual/right_arm_link4.obj"/>
    <mesh name="right_arm_link5" file="visual/right_arm_link5.obj"/>
    <mesh name="right_arm_link6" file="visual/right_arm_link6.obj"/>
    <mesh name="right_arm_link7" file="visual/right_arm_link7.obj"/>

    <!-- collision meshes -->
    <mesh name="base_link_collision" file="collision/base_link.stl"/>
    <mesh name="torso_link0_collision" file="collision/torso_link0.stl"/>
    <mesh name="torso_link1_collision" file="collision/torso_link1.stl"/>
    <mesh name="torso_link2_collision" file="collision/torso_link2.stl"/>
    <mesh name="torso_link3_collision" file="collision/torso_link3.stl"/>
    <mesh name="head_link1_collision" file="collision/head_link1.stl"/>
    <mesh name="head_link2_collision" file="collision/head_link2.stl"/>
    <mesh name="head_link3_collision" file="collision/head_link3.stl"/>
    <mesh name="left_arm_link0_collision" file="collision/left_arm_link0.stl"/>
    <mesh name="left_arm_link1_collision" file="collision/left_arm_link1.stl"/>
    <mesh name="left_arm_link2_collision" file="collision/left_arm_link2.stl"/>
    <mesh name="left_arm_link3_collision" file="collision/left_arm_link3.stl"/>
    <mesh name="left_arm_link4_collision" file="collision/left_arm_link4.stl"/>
    <mesh name="left_arm_link5_collision" file="collision/left_arm_link5.stl"/>
    <mesh name="left_arm_link6_collision" file="collision/left_arm_link6.stl"/>
    <mesh name="left_arm_link7_collision" file="collision/left_arm_link7.stl"/>
    <mesh name="right_arm_link0_collision" file="collision/right_arm_link0.stl"/>
    <mesh name="right_arm_link1_collision" file="collision/right_arm_link1.stl"/>
    <mesh name="right_arm_link2_collision" file="collision/right_arm_link2.stl"/>
    <mesh name="right_arm_link3_collision" file="collision/right_arm_link3.stl"/>
    <mesh name="right_arm_link4_collision" file="collision/right_arm_link4.stl"/>
    <mesh name="right_arm_link5_collision" file="collision/right_arm_link5.stl"/>
    <mesh name="right_arm_link6_collision" file="collision/right_arm_link6.stl"/>
    <mesh name="right_arm_link7_collision" file="collision/right_arm_link7.stl"/>
  </asset>
  <worldbody>
    <light directional="true" diffuse=".4 .4 .4" specular="0.1 0.1 0.1" pos="0 0 5.0" dir="0 0 -1" castshadow="false"/>
    <light directional="true" diffuse=".6 .6 .6" specular="0.2 0.2 0.2" pos="0 0 4" dir="0 0 -1" castshadow="false"/>
    <geom name="ground" type="plane" size="0 0 1" pos="0.001 0 0" quat="1 0 0 0" material="matplane" condim="1" conaffinity='15'/>

    <body childclass="humanoid" name="humanoid_container" pos="0.5 0 -0.1" euler="0.0 0 3.14">
      <include file="torobo2/humanoid_bare.xml"/>
      <freejoint/>
    </body>

    <body name="base_link_trans_x" pos="0 0 0">
      <inertial pos="0 0 0" mass="0.00001" diaginertia="0.00001 0.00001 0.00001"/>
      <joint name="base_joint_trans_x" type="slide" axis="1 0 0" range="-10000 10000"/>
      <body name="base_link_trans_y" pos="0 0 0">
        <inertial pos="0 0 0" mass="0.00001" diaginertia="0.00001 0.00001 0.00001"/>
        <joint name="base_joint_trans_y" type="slide" axis="0 1 0" range="-10000 10000"/>
        <body name="base_link_rot_yaw" pos="0 0 0">
          <inertial pos="0 0 0" mass="0.00001" diaginertia="0.00001 0.00001 0.00001"/>
          <joint name="base_joint_rot_yaw" type="hinge" axis="0 0 1" range="-10000 10000"/>
          <body name="base_link" pos="0 0 0" childclass="torobo2">
            <inertial pos="-0.0231104 0.00158473 0.188355" quat="-0.0157449 0.686078 -0.018153 0.727131" mass="56.049" diaginertia="1.87057 1.70163 1.51139"/>
            <geom class="visual" type="mesh" mesh="base_link" material="219,219,219"/>
            <geom class="collision" type="capsule" size="0.25" fromto="0 -0.2 0.25 0.0 0.2 0.25"/>
            <geom class="visual" pos="0 0 0.34" type="mesh" mesh="torso_link0" material="219,219,219"/>
            <!-- <geom class="collision" type="capsule" size="0.1" fromto="0 -0.0 0 0.0 0.5 0"/> -->
            <body name="torso/link_1" pos="0 0 0.425" quat="0.5 -0.5 -0.5 -0.5">
              <inertial pos="0.213191 -0.019853 -0.001309" quat="0.00960405 0.690592 -0.00415758 0.723169" mass="11.5246" diaginertia="0.313471 0.30707 0.0289366"/>
              <joint name="torso/joint_1" pos="0 0 0" axis="0 0 1" range="-0.959931 0.610865"/>
              <geom class="visual" type="mesh" mesh="torso_link1_0" material="72,71,61"/>
              <geom class="visual" type="mesh" mesh="torso_link1_1" material="219,219,219"/>
              <body name="torso/link_2" pos="0.45 0 0" quat="0.707107 0 0 0.707107">
                <inertial pos="1e-05 -0.039264 0.007875" quat="0.647558 0.762016 0.000151212 0.000100433" mass="2.8715" diaginertia="0.0121864 0.0119528 0.00777284"/>
                <joint name="torso/joint_2" pos="0 0 0" axis="0 0 1" range="-0.523599 2.18166"/>
                <geom class="visual" type="mesh" mesh="torso_link2" material="219,219,219"/>
                <geom class="collision" type="capsule" size="0.1" fromto="0 -0.0 0 0.0 0.5 0"/>
                <body name="torso/link_3" quat="0.707107 0.707107 0 0">
                  <inertial pos="-0.0127522 0.00183622 0.30238" quat="0.999869 0.00116029 0.0160629 0.00154784" mass="10.0047" diaginertia="0.166033 0.150799 0.0601367"/>
                  <joint name="torso/joint_3" pos="0 0 0" axis="0 0 1" range="-2.0944 2.0944"/>
                  <geom class="visual" type="mesh" mesh="torso_link3" material="219,219,219"/>
                  <geom class="collision" type="capsule" size="0.15" fromto="0 0 0.15 0. 0. 0.35"/>
                  <geom class="visual" pos="0 0.03465 0.3416" quat="0.5 0.5 0.5 -0.5" type="mesh" mesh="left_arm_link0" material="219,219,219"/>
                  <!-- <geom class="collision" pos="0 0.03465 0.3416" quat="0.5 0.5 0.5 -0.5" type="mesh" mesh="left_arm_link0_collision"/> -->
                  <geom class="visual" pos="0 -0.03465 0.3416" quat="0.5 0.5 0.5 -0.5" type="mesh" mesh="right_arm_link0" material="219,219,219"/>
                  <!-- <geom class="collision" pos="0 -0.03465 0.3416" quat="0.5 0.5 0.5 -0.5" type="mesh" mesh="right_arm_link0_collision"/> -->
                  <body name="left_arm/link_1" pos="0 0.22035 0.418519" quat="0.392847 0.587938 0.587938 -0.392847">
                    <inertial pos="0.007282 -0.002236 0.061573" quat="0.706031 -0.0605284 -0.0482315 0.703939" mass="2.34532" diaginertia="0.00996609 0.00950611 0.0029046"/>
                    <joint name="left_arm/joint_1" pos="0 0 0" axis="0 0 1" range="-1.22173 4.18879" ref="-0.5"/>
                    <geom class="visual" type="mesh" mesh="left_arm_link1_0" material="72,71,61"/>
                    <geom class="visual" type="mesh" mesh="left_arm_link1_1" material="219,219,219"/>
                    <geom class="collision" type="capsule" size="0.06" fromto="0 0 -0.01 0 0 0.03"/>
                    <body name="left_arm/link_2" pos="0.02 0 0" quat="0.587938 0.587938 0.392847 -0.392847">
                      <inertial pos="0.001632 0.064705 0.003689" quat="0.740303 0.672149 -0.00176482 0.0127677" mass="1.92983" diaginertia="0.0070432 0.00669025 0.00256541"/>
                      <joint name="left_arm/joint_2" pos="0 0 0" axis="0 0 1" range="-1.91986 0" ref="0.2"/>
                      <geom class="visual" type="mesh" mesh="left_arm_link2" material="219,219,219"/>
                      <geom class="collision" type="capsule" size="0.06" fromto="0 0 0 0.0 0.3 0"/>
                      <body name="left_arm/link_3" pos="0 0.3 0" quat="0.5 0.5 0.5 -0.5">
                        <inertial pos="0.006987 -0.002219 0.07002" quat="0.998294 -0.0116747 -0.0549101 0.0160829" mass="2.41136" diaginertia="0.0121108 0.0120041 0.00296219"/>
                        <joint name="left_arm/joint_3" pos="0 0 0" axis="0 0 1" range="-2.0944 2.0944" />
                        <geom class="visual" type="mesh" mesh="left_arm_link3_0" material="72,71,61"/>
                        <geom class="visual" type="mesh" mesh="left_arm_link3_1" material="219,219,219"/>
                        <geom class="collision" type="capsule" size="0.06" fromto="0 0 0 0 0 -0.3"/>
                        <body name="left_arm/link_4" pos="0.02 0 0" quat="0.707107 0.707107 0 0">
                          <inertial pos="-0.011045 -0.047406 0.003626" quat="0.673288 0.732855 -0.0679342 -0.0706561" mass="1.16816" diaginertia="0.0040733 0.00384647 0.001413"/>
                          <joint name="left_arm/joint_4" pos="0 0 0" axis="0 0 1" range="-0.0872665 2.35619" ref="-0.9"/>
                          <geom class="visual" type="mesh" mesh="left_arm_link4" material="219,219,219"/>
                          <geom class="collision" type="capsule" size="0.06" fromto="0 0 -0.02 0 0 0.02"/>
                          <body name="left_arm/link_5" pos="-0.02 -0.3 0" quat="0.5 -0.5 -0.5 -0.5">
                            <inertial pos="-3e-06 0.011867 0.099758" quat="0.990044 0.140741 -0.00033647 -0.00199369" mass="1.13531" diaginertia="0.00300474 0.00292652 0.000794792"/>
                            <joint name="left_arm/joint_5" pos="0 0 0" axis="0 0 1" range="-1.5708 1.5708"/>
                            <geom class="visual" type="mesh" mesh="left_arm_link5" material="219,219,219"/>
                            <!-- <geom class="collision" type="mesh" mesh="left_arm_link5_collision"/> -->
                            <body name="left_arm/link_6" quat="0.5 0.5 0.5 -0.5">
                              <inertial pos="1.5e-05 0.002262 -0.003468" quat="0.997384 -0.0720286 0.000853523 0.00598791" mass="0.737707" diaginertia="0.000683267 0.000624344 0.000429623"/>
                              <joint name="left_arm/joint_6" pos="0 0 0" axis="0 0 1" range="-1.5708 1.5708"/>
                              <geom class="visual" type="mesh" mesh="left_arm_link6" material="219,219,219"/>
                              <!-- <geom class="collision" type="mesh" mesh="left_arm_link6_collision"/> -->
                              <body name="left_arm/link_7" pos="0 0.048 0.01" quat="0.707107 0.707107 0 0">
                                <inertial pos="0.00017 2.7e-05 0.01376" quat="0.52141 0.478267 -0.520329 0.478174" mass="0.14265" diaginertia="7.31843e-05 5.09235e-05 4.92308e-05"/>
                                <joint name="left_arm/joint_7" pos="0 0 0" axis="0 0 1" range="-0.349066 1.5708"/>
                                <geom class="visual" type="mesh" mesh="left_arm_link7" material="72,71,61"/>
                                <!-- <geom class="collision" type="mesh" mesh="left_arm_link7_collision"/> -->
                              </body>
                            </body>
                          </body>
                        </body>
                      </body>
                    </body>
                  </body>
                  <body name="right_arm/link_1" pos="0 -0.22035 0.418519" quat="0.587938 0.392847 0.392847 -0.587938">
                    <inertial pos="0.007282 0.002236 -0.061573" quat="0.703939 0.0482315 0.0605284 0.706031" mass="2.34532" diaginertia="0.00996609 0.00950611 0.0029046"/>
                    <joint name="right_arm/joint_1" pos="0 0 0" axis="0 0 1" range="-1.22173 4.18879" ref="-0.5"/>
                    <geom class="visual" type="mesh" mesh="right_arm_link1_0" material="72,71,61"/>
                    <geom class="visual" type="mesh" mesh="right_arm_link1_1" material="219,219,219"/>
                    <geom class="collision" type="capsule" size="0.06" fromto="0 0 -0.04 0 0 0.01"/>

                    <body name="right_arm/link_2" pos="0.02 0 0" quat="0.587938 -0.587938 -0.392847 -0.392847">
                      <inertial pos="0.001632 0.064705 0.003689" quat="0.740303 0.672149 -0.00176482 0.0127677" mass="1.92983" diaginertia="0.0070432 0.00669025 0.00256541"/>
                      <joint name="right_arm/joint_2" pos="0 0 0" axis="0 0 1" range="-1.91986 0" ref="0.2"/>
                      <geom class="visual" type="mesh" mesh="right_arm_link2"  material="219,219,219"/>
                      <geom class="collision" type="capsule" size="0.06" fromto="0 0 0 0. 0.3 0"/>
                      <body name="right_arm/link_3" pos="0 0.3 0" quat="0.5 -0.5 -0.5 -0.5">
                        <inertial pos="0.006987 0.002219 -0.07002" quat="0.998294 -0.0116747 0.0549101 -0.0160829" mass="2.41136" diaginertia="0.0121108 0.0120041 0.00296219"/>
                        <joint name="right_arm/joint_3" pos="0 0 0" axis="0 0 1" range="-2.0944 2.0944"/>
                        <geom class="visual" type="mesh" mesh="right_arm_link3_0"  material="72,71,61"/>
                        <geom class="visual" type="mesh" mesh="right_arm_link3_1"  material="219,219,219"/>
                        <geom class="collision" type="capsule" size="0.06" fromto="0 0 0 0 0 0.3"/>
                        <body name="right_arm/link_4" pos="0.02 0 0" quat="0.707107 -0.707107 0 0">
                          <inertial pos="-0.011045 -0.047406 0.003626" quat="0.673288 0.732855 -0.0679342 -0.0706561" mass="1.16816" diaginertia="0.0040733 0.00384647 0.001413"/>
                          <joint name="right_arm/joint_4" pos="0 0 0" axis="0 0 1" range="-0.0872665 2.35619" ref="-0.9"/>
                          <geom class="visual" type="mesh" mesh="right_arm_link4"  material="219,219,219"/>
                          <geom class="collision" type="capsule" size="0.06" fromto="0 0 -0.02 0 0 0.02"/>
                          <body name="right_arm/link_5" pos="-0.02 -0.3 0" quat="0.5 0.5 0.5 -0.5">
                            <inertial pos="3e-06 0.011867 -0.099758" quat="0.990044 -0.140741 -0.00033647 0.00199369" mass="1.13531" diaginertia="0.00300474 0.00292652 0.000794792"/>
                            <joint name="right_arm/joint_5" pos="0 0 0" axis="0 0 1" range="-1.5708 1.5708"/>
                            <geom class="visual" type="mesh" mesh="right_arm_link5"  material="219,219,219"/>
                            <!-- <geom class="collision" type="capsule" size="0.06" fromto="0 0 0 0 0 0.03"/> -->
                            <body name="right_arm/link_6" quat="0.5 -0.5 -0.5 -0.5">
                              <inertial pos="1.5e-05 -0.002262 0.003468" quat="0.997384 -0.0720286 -0.000853523 -0.00598791" mass="0.737707" diaginertia="0.000683267 0.000624344 0.000429623"/>
                              <joint name="right_arm/joint_6" pos="0 0 0" axis="0 0 1" range="-1.5708 1.5708"/>
                              <geom class="visual" type="mesh" mesh="right_arm_link6"  material="219,219,219"/>
                              <!-- <geom class="collision" type="capsule" size="0.06" fromto="0 0 0 0 0 0.03"/> -->
                              <body name="right_arm/link_7" pos="0 0.048 -0.01" quat="0.707107 -0.707107 0 0">
                                <inertial pos="0.00017 -2.7e-05 -0.01376" quat="0.478174 0.520329 -0.478267 0.52141" mass="0.14265" diaginertia="7.31843e-05 5.09235e-05 4.92308e-05"/>
                                <joint name="right_arm/joint_7" pos="0 0 0" axis="0 0 1" range="-0.349066 1.5708"/>
                                <geom class="visual" type="mesh" mesh="right_arm_link7"  material="72,71,61"/>
                                <!-- <geom class="collision" type="capsule" size="0.06" fromto="0 0 0 0 0 0.03"/> -->
                              </body>
                            </body>
                          </body>
                        </body>
                      </body>
                    </body>
                  </body>
                  <body name="head/link_1" pos="0 0 0.53">
                    <inertial pos="-0.012467 -0.004271 -0.021697" quat="0.683565 -0.0689821 -0.121402 0.716409" mass="0.581793" diaginertia="0.00103142 0.000928712 0.000277733"/>
                    <joint name="head/joint_1" pos="0 0 0" axis="0 0 1" range="-2.96706 2.96706"/>
                    <geom class="visual" type="mesh" mesh="head_link1" material="72,71,61"/>
                    <!-- <geom class="collision" type="capsule" size="0.1" fromto="0 -0.0 0 0.0 0.5 0"/> -->
                    <body name="head/link_2" pos="-0.02 0 0" quat="0.5 -0.5 -0.5 -0.5">
                      <inertial pos="0.028956 -0.032951 0.000172" quat="0.661731 0.647513 0.279151 0.25478" mass="0.321723" diaginertia="0.000479673 0.000405915 0.000249251"/>
                      <joint name="head/joint_2" pos="0 0 0" axis="0 0 1" range="-0.872665 1.0472"/>
                      <geom class="visual" type="mesh" mesh="head_link2" material="219,219,219"/>
                      <!-- <geom class="collision" type="capsule" size="0.1" fromto="0 -0.0 0 0.0 0.5 0"/> -->
                      <body name="head/link_3" pos="0.041 0 0" quat="0.707107 -0.707107 0 0">
                        <inertial pos="0.097293 0.000224 0.034755" quat="0.981108 0.000352451 0.193328 -0.00720088" mass="1.38491" diaginertia="0.00840426 0.00768934 0.00440097"/>
                        <joint name="head/joint_3" pos="0 0 0" axis="0 0 1" range="-0.872665 0.872665"/>
                        <geom class="visual" type="mesh" mesh="head_link3_0" material="72,71,61" />
                        <geom class="visual" type="mesh" mesh="head_link3_1" material="210,210,210" />
                        <geom class="collision" type="capsule" size="0.12" fromto="0.05 -0.1 0 0.05 0.1 0"/>
                      </body>
                    </body>
                  </body>
                </body>
              </body>
            </body>
          </body>
          <!-- wheel collision is disabled -->
          <body name="base_front_right_wheel/link" pos="0.15 -0.221475 0.07582" quat="0.707107 -0.707107 0 0">
            <inertial pos="0 0 -0.000427" quat="0.5 0.5 -0.5 0.5" mass="1.05512" diaginertia="0.00362702 0.00213355 0.00213355"/>
            <joint name="base_front_right_wheel/joint" pos="0 0 0" axis="0 0 1"/>
            <geom class="visual" type="mesh" mesh="right_wheel_link_0" material="190,188,186"/>
            <geom class="visual" type="mesh" mesh="right_wheel_link_1" material="192,192,192"/>
          </body>
          <body name="base_front_left_wheel/link" pos="0.15 0.221475 0.07582" quat="0.707107 -0.707107 0 0">
            <inertial pos="0 0 0" quat="0.5 0.5 -0.5 0.5" mass="1.05512" diaginertia="0.00362702 0.00213355 0.00213355"/>
            <joint name="base_front_left_wheel/joint" pos="0 0 0" axis="0 0 1"/>
            <geom class="visual" type="mesh" mesh="left_wheel_link_0" material="190,188,186"/>
            <geom class="visual" type="mesh" mesh="left_wheel_link_1" material="192,192,192"/>
          </body>
          <body name="base_rear_right_wheel/link" pos="-0.15 -0.221475 0.07582" quat="0.707107 -0.707107 0 0">
            <inertial pos="0 0 0" quat="0.5 0.5 -0.5 0.5" mass="1.05512" diaginertia="0.00362702 0.00213355 0.00213355"/>
            <joint name="base_rear_right_wheel/joint" pos="0 0 0" axis="0 0 1"/>
            <geom class="visual" type="mesh" mesh="left_wheel_link_0" material="190,188,186"/>
            <geom class="visual" type="mesh" mesh="left_wheel_link_1" material="192,192,192"/>
          </body>
          <body name="base_rear_left_wheel/link" pos="-0.15 0.221475 0.07582" quat="0.707107 -0.707107 0 0">
            <inertial pos="0 0 -0.000427" quat="0.5 0.5 -0.5 0.5" mass="1.05512" diaginertia="0.00362702 0.00213355 0.00213355"/>
            <joint name="base_rear_left_wheel/joint" pos="0 0 0" axis="0 0 1"/>
            <geom class="visual" type="mesh" mesh="right_wheel_link_0" material="190,188,186"/>
            <geom class="visual" type="mesh" mesh="right_wheel_link_1" material="192,192,192"/>
          </body>
        </body>
      </body>
    </body>
  </worldbody>
  <contact>
    <exclude body1="base_link" body2="head/link_1"/>
    <exclude body1="base_link" body2="head/link_2"/>
    <exclude body1="base_link" body2="head/link_3"/>
    <exclude body1="base_link" body2="torso/link_1"/>
    <exclude body1="base_link" body2="torso/link_2"/>
    <exclude body1="base_link" body2="torso/link_3"/>
    <exclude body1="head/link_1" body2="head/link_2"/>
    <exclude body1="head/link_1" body2="head/link_3"/>
    <exclude body1="head/link_1" body2="left_arm/link_1"/>
    <exclude body1="head/link_1" body2="left_arm/link_2"/>
    <exclude body1="head/link_1" body2="right_arm/link_1"/>
    <exclude body1="head/link_1" body2="right_arm/link_2"/>
    <exclude body1="head/link_1" body2="torso/link_1"/>
    <exclude body1="head/link_1" body2="torso/link_2"/>
    <exclude body1="head/link_1" body2="torso/link_3"/>
    <exclude body1="head/link_2" body2="head/link_3"/>
    <exclude body1="head/link_2" body2="left_arm/link_1"/>
    <exclude body1="head/link_2" body2="left_arm/link_2"/>
    <exclude body1="head/link_2" body2="right_arm/link_1"/>
    <exclude body1="head/link_2" body2="right_arm/link_2"/>
    <exclude body1="head/link_2" body2="torso/link_1"/>
    <exclude body1="head/link_2" body2="torso/link_2"/>
    <exclude body1="head/link_2" body2="torso/link_3"/>
    <exclude body1="head/link_3" body2="left_arm/link_1"/>
    <exclude body1="head/link_3" body2="right_arm/link_1"/>
    <exclude body1="head/link_3" body2="torso/link_1"/>
    <exclude body1="head/link_3" body2="torso/link_2"/>
    <exclude body1="left_arm/link_1" body2="left_arm/link_2"/>
    <exclude body1="left_arm/link_1" body2="left_arm/link_3"/>
    <exclude body1="left_arm/link_1" body2="left_arm/link_4"/>
    <exclude body1="left_arm/link_1" body2="left_arm/link_5"/>
    <exclude body1="left_arm/link_1" body2="left_arm/link_6"/>
    <exclude body1="left_arm/link_1" body2="left_arm/link_7"/>
    <exclude body1="left_arm/link_1" body2="right_arm/link_1"/>
    <exclude body1="left_arm/link_1" body2="right_arm/link_2"/>
    <exclude body1="left_arm/link_1" body2="right_arm/link_3"/>
    <exclude body1="left_arm/link_1" body2="right_arm/link_4"/>
    <exclude body1="left_arm/link_1" body2="torso/link_1"/>
    <exclude body1="left_arm/link_1" body2="torso/link_2"/>
    <exclude body1="left_arm/link_1" body2="torso/link_3"/>
    <exclude body1="left_arm/link_2" body2="left_arm/link_3"/>
    <exclude body1="left_arm/link_2" body2="left_arm/link_4"/>
    <exclude body1="left_arm/link_2" body2="left_arm/link_5"/>
    <exclude body1="left_arm/link_2" body2="left_arm/link_6"/>
    <exclude body1="left_arm/link_2" body2="left_arm/link_7"/>
    <exclude body1="left_arm/link_2" body2="right_arm/link_1"/>
    <exclude body1="left_arm/link_2" body2="right_arm/link_2"/>
    <exclude body1="left_arm/link_2" body2="right_arm/link_3"/>
    <exclude body1="left_arm/link_2" body2="torso/link_1"/>
    <exclude body1="left_arm/link_2" body2="torso/link_2"/>
    <exclude body1="left_arm/link_3" body2="left_arm/link_4"/>
    <exclude body1="left_arm/link_3" body2="left_arm/link_5"/>
    <exclude body1="left_arm/link_3" body2="left_arm/link_6"/>
    <exclude body1="left_arm/link_3" body2="left_arm/link_7"/>
    <exclude body1="left_arm/link_3" body2="right_arm/link_1"/>
    <exclude body1="left_arm/link_3" body2="right_arm/link_2"/>
    <exclude body1="left_arm/link_4" body2="left_arm/link_5"/>
    <exclude body1="left_arm/link_4" body2="left_arm/link_6"/>
    <exclude body1="left_arm/link_4" body2="left_arm/link_7"/>
    <exclude body1="left_arm/link_4" body2="right_arm/link_1"/>
    <exclude body1="left_arm/link_5" body2="left_arm/link_6"/>
    <exclude body1="left_arm/link_5" body2="left_arm/link_7"/>
    <exclude body1="left_arm/link_6" body2="left_arm/link_7"/>
    <exclude body1="right_arm/link_1" body2="right_arm/link_2"/>
    <exclude body1="right_arm/link_1" body2="right_arm/link_3"/>
    <exclude body1="right_arm/link_1" body2="right_arm/link_4"/>
    <exclude body1="right_arm/link_1" body2="right_arm/link_5"/>
    <exclude body1="right_arm/link_1" body2="right_arm/link_6"/>
    <exclude body1="right_arm/link_1" body2="right_arm/link_7"/>
    <exclude body1="right_arm/link_1" body2="torso/link_1"/>
    <exclude body1="right_arm/link_1" body2="torso/link_2"/>
    <exclude body1="right_arm/link_1" body2="torso/link_3"/>
    <exclude body1="right_arm/link_2" body2="right_arm/link_3"/>
    <exclude body1="right_arm/link_2" body2="right_arm/link_4"/>
    <exclude body1="right_arm/link_2" body2="right_arm/link_5"/>
    <exclude body1="right_arm/link_2" body2="right_arm/link_6"/>
    <exclude body1="right_arm/link_2" body2="right_arm/link_7"/>
    <exclude body1="right_arm/link_2" body2="torso/link_1"/>
    <exclude body1="right_arm/link_2" body2="torso/link_2"/>
    <exclude body1="right_arm/link_3" body2="right_arm/link_4"/>
    <exclude body1="right_arm/link_3" body2="right_arm/link_5"/>
    <exclude body1="right_arm/link_3" body2="right_arm/link_6"/>
    <exclude body1="right_arm/link_3" body2="right_arm/link_7"/>
    <exclude body1="right_arm/link_4" body2="right_arm/link_5"/>
    <exclude body1="right_arm/link_4" body2="right_arm/link_6"/>
    <exclude body1="right_arm/link_4" body2="right_arm/link_7"/>
    <exclude body1="right_arm/link_5" body2="right_arm/link_6"/>
    <exclude body1="right_arm/link_5" body2="right_arm/link_7"/>
    <exclude body1="right_arm/link_6" body2="right_arm/link_7"/>
    <exclude body1="torso/link_1" body2="torso/link_2"/>
    <exclude body1="torso/link_1" body2="torso/link_3"/>
    <exclude body1="torso/link_2" body2="torso/link_3"/>
    <exclude body1="base_link" body2="left_arm/link_1"/>
    <exclude body1="head/link_3" body2="left_arm/link_2"/>
    <exclude body1="base_link" body2="right_arm/link_1"/>
    <exclude body1="head/link_3" body2="right_arm/link_2"/>
  </contact>
  <actuator>
    <velocity name="robot/base_joint_trans_x" joint="base_joint_trans_x" ctrlrange="-10 10" kv="10000"/>
    <velocity name="robot/base_joint_trans_y" joint="base_joint_trans_y" ctrlrange="-10 10" kv="10000"/>
    <velocity name="robot/base_joint_rot_yaw" joint="base_joint_rot_yaw" ctrlrange="-10 10" kv="10000"/>
    <position name="robot/torso/joint_1" joint="torso/joint_1" ctrlrange="-0.959931 0.610865" forcerange="-400 400" kp="10000" kv="1000"/>
    <position name="robot/torso/joint_2" joint="torso/joint_2" ctrlrange="-0.523599 2.18166" forcerange="-250 250" kp="10000" kv="1000"/>
    <position name="robot/torso/joint_3" joint="torso/joint_3" ctrlrange="-2.0944 2.0944" forcerange="-300 300" kp="10000" kv="1000"/>
    <position name="robot/left_arm/joint_1" joint="left_arm/joint_1" ctrlrange="-1.22173 4.18879" forcerange="-135 135" kp="10000" kv="1000"/>
    <position name="robot/left_arm/joint_2" joint="left_arm/joint_2" ctrlrange="-1.91986 0" forcerange="-75 75" kp="10000" kv="1000"/>
    <position name="robot/left_arm/joint_3" joint="left_arm/joint_3" ctrlrange="-2.0944 2.0944" forcerange="-75 75" kp="10000" kv="1000"/>
    <position name="robot/left_arm/joint_4" joint="left_arm/joint_4" ctrlrange="-0.0872665 2.35619" forcerange="-75 75" kp="10000" kv="1000"/>
    <position name="robot/left_arm/joint_5" joint="left_arm/joint_5" ctrlrange="-1.5708 1.5708" forcerange="-30 30" kp="10000" kv="1000"/>
    <position name="robot/left_arm/joint_6" joint="left_arm/joint_6" ctrlrange="-1.5708 1.5708" forcerange="-30 30" kp="10000" kv="1000"/>
    <position name="robot/left_arm/joint_7" joint="left_arm/joint_7" ctrlrange="-0.349066 1.5708" forcerange="-30 30" kp="10000" kv="1000"/>
    <position name="robot/right_arm/joint_1" joint="right_arm/joint_1" ctrlrange="-1.22173 4.18879" forcerange="-135 135" kp="10000" kv="1000"/>
    <position name="robot/right_arm/joint_2" joint="right_arm/joint_2" ctrlrange="-1.91986 0" forcerange="-75 75" kp="10000" kv="1000"/>
    <position name="robot/right_arm/joint_3" joint="right_arm/joint_3" ctrlrange="-2.0944 2.0944" forcerange="-75 75" kp="10000" kv="1000"/>
    <position name="robot/right_arm/joint_4" joint="right_arm/joint_4" ctrlrange="-0.0872665 2.35619" forcerange="-75 75" kp="10000" kv="1000"/>
    <position name="robot/right_arm/joint_5" joint="right_arm/joint_5" ctrlrange="-1.5708 1.5708" forcerange="-30 30" kp="10000" kv="1000"/>
    <position name="robot/right_arm/joint_6" joint="right_arm/joint_6" ctrlrange="-1.5708 1.5708" forcerange="-30 30" kp="10000" kv="1000"/>
    <position name="robot/right_arm/joint_7" joint="right_arm/joint_7" ctrlrange="-0.349066 1.5708" forcerange="-30 30" kp="10000" kv="1000"/>
    <position name="robot/head/joint_1" joint="head/joint_1" ctrlrange="-2.96706 2.96706" forcerange="-6 6" kp="100" kv="10"/>
    <position name="robot/head/joint_2" joint="head/joint_2" ctrlrange="-0.872665 1.0472" forcerange="-6 6" kp="100" kv="10"/>
    <position name="robot/head/joint_3" joint="head/joint_3" ctrlrange="-0.872665 0.872665" forcerange="-6 6" kp="100" kv="10"/>
    <!-- human -->
    <general class="humanoid" gear="100" joint="abdomen_y" name="abdomen_y" biasprm="0 -0.004 0"/>
    <general class="humanoid" gear="100" joint="abdomen_z" name="abdomen_z" biasprm="0 -0.004 0" />
    <general class="humanoid" gear="100" joint="abdomen_x" name="abdomen_x" biasprm="0 -0.004 0" />
    <general class="humanoid" gear="100" joint="right_hip_x" name="right_hip_x" biasprm="0 -0.004 0" />
    <general class="humanoid" gear="100" joint="right_hip_z" name="right_hip_z" biasprm="0 -0.004 0" />
    <general class="humanoid" gear="300" joint="right_hip_y" name="right_hip_y" biasprm="0 -0.0005 0" />
    <general class="humanoid" gear="200" joint="right_knee" name="right_knee" biasprm="0 -0.000 0" />
    <general class="humanoid" gear="100" joint="left_hip_x" name="left_hip_x" biasprm="0 -0.004 0" />
    <general class="humanoid" gear="100" joint="left_hip_z" name="left_hip_z" biasprm="0 -0.004 0" />
    <general class="humanoid" gear="300" joint="left_hip_y" name="left_hip_y" biasprm="0 -0.0005 0" />
    <general class="humanoid" gear="200" joint="left_knee" name="left_knee" biasprm="0 -0.000 0" />
    <general class="humanoid" gear="25" joint="right_shoulder1" name="right_shoulder1" biasprm="0 -0.001 0"/>
    <general class="humanoid" gear="25" joint="right_shoulder2" name="right_shoulder2" biasprm="0 -0.001 0"/>
    <general class="humanoid" gear="25" joint="right_elbow" name="right_elbow" biasprm="0 -0.001 0" />
    <general class="humanoid" gear="25" joint="left_shoulder1" name="left_shoulder1" biasprm="0 -0.001 0"/>
    <general class="humanoid" gear="25" joint="left_shoulder2" name="left_shoulder2" biasprm="0 -0.001 0"/>
    <general class="humanoid" gear="25" joint="left_elbow" name="left_elbow" biasprm="0 -0.001 0"/>
  </actuator>
</mujoco>
